Workbook

Sheet Master
B2: Aaron D | D2: Andrew M | F2: Caleb K | H2: Chris G | J2: Colby L | L2: Dawson O
A3: Pos | B3: Player | C3: $ | D3: Player | E3: $ | F3: Player | G3: $ | H3: Player | I3: $ | J3: Player | K3: $ | L3: Player | M3: $ | N3: Pos | Q3: 51
A4: QB | B4: T Tagovailoa | C4: 13 | D4: R Tanehill | E4: 3 | F4: L Jackson | G4: 17 | H4: D Prescott | I4: 8 | J4: M Jones | K4: 7 | L4: J Allen | M4: 16 | N4: QB
A5: QB | B5: P. Mahomes | C5: 15 | D5: T Lance | E5: 3 | F5: K Pickett | G5: 5 | H5: M Stafford | I5: 3 | J5: K Cousins | K5: 1 | L5: D Carr | M5: 3 | N5: QB | P5: 3
A6: QB | F6: T Brady | G6: 3 | N6: QB
A7: QB | F7: D Watson | G7: 2 | N7: QB
A8: RB | B8: J Taylor | C8: 42 | D8: N Harris | E8: 50 | F8: J Taylor | G8: 42 | H8: A Ekeler | I8: 29 | J8: N Chubb | K8: 44 | L8: D Henry | M8: 50 | N8: RB
A9: RB | B9: D Swift | C9: 12 | D9: A Gibson | E9: 36 | F9: JK Dobbins | G9: 3 | H9: J Jacobs | I9: 28 | J9: C Edwards-H | K9: 30 | L9: A Jones | M9: 32 | N9: RB
A10: RB | B10: C Edmonds | C10: 7 | D10: T Pollard | E10: 1 | F10: D Singletary | G10: 3 | H10: I Spiller | I10: 6 | J10: M Sanders | K10: 22 | L10: K Hunt | M10: 6 | N10: RB | P10: 12
A11: RB | B11: B Hall | C11: 28 | D11: K Walker | E11: 14 | F11: K Drake | G11: 2 | H11: R White | I11: 4 | J11: AJ Dillon | K11: 5 | L11: R. Mostert | M11: 9 | N11: RB
A12: RB | B12: C Akers | C12: 3 | D12: M. Ingram | E12: 4 | F12: D. Pierce | G12: 29 | H12: J Connor | I12: 2 | J12: D Henderson | K12: 5 | L12: T Allgeier | M12: 5 | N12: RB
A13: RB | B13: K Gainwell | C13: 2 | F13: R Stevenson | G13: 1 | H13: N Hines | I13: 1 | J13: L Fournette | K13: 4 | N13: RB
A14: RB | B14: T Etienne | C14: 1 | H14: J White | I14: 1 | J14: J. Cook | K14: 12 | N14: RB
A15: RB | J15: K Herbert | K15: 3 | N15: RB
A16: RB | J16: Z White | K16: 4 | N16: RB
A17: WR | B17: AJ Brown | C17: 28 | D17: S Diggs | E17: 45 | F17: T Hill | G17: 37 | H17: K Allen | I17: 24 | J17: T McLaughlin | K17: 27 | L17: D. Hopkins | M17: 31 | N17: WR
A18: WR | B18: DJ Moore | C18: 18 | D18: C Olave | E18: 18 | F18: R Woods | G18: 15 | H18: C Lamb | I18: 20 | J18: D Johnson | K18: 16 | L18: D Samuel | M18: 7 | N18: WR
A19: WR | B19: D Smith | C19: 11 | D19: B Aiyuk | E19: 15 | F19: C Godwin | G19: 15 | H19: G Pickens | I19: 12 | J19: J Jeudy | K19: 14 | L19: J Chase | M19: 6 | N19: WR
A20: WR | B20: K. Toney | C20: 20 | D20: M Thomas | E20: 7 | F20: J Landry | G20: 3 | H20: R Doubs | I20: 8 | J20: C Watson | K20: 7 | L20: G Davis | M20: 5 | N20: WR | P20: 10
A21: WR | B21: J Waddle | C21: 8 | D21: G Wilson | E21: 6 | F21: W Fuller | G21: 2 | H21: C Davis | I21: 3 | J21: DJ Chark | K21: 3 | L21: R Anderson | M21: 3 | N21: WR
A22: WR | B22: J Smith-Sch. | C22: 6 | D22: D Mooney | E22: 3 | F22: E Moore | G22: 3 | H22: S Shepard | I22: 1 | J22: M Brown | K22: 1 | L22: M Williams | M22: 1 | N22: WR
A23: WR | B23: C Ridley | C23: 6 | D23: B Edwards | E23: 1 | F23: J. Dotson | G23: 7 | H23: R Bateman | I23: 1 | J23: M Jones | K23: 1 | N23: WR
A24: WR | D24: J Meyers | E24: 1 | F24: J Williams | G24: 9 | J24: D Brown | K24: 1 | N24: WR
A25: WR | B25: M Pittman | C25: 2 | J25: D Bell | K25: 2 | N25: WR
A26: WR | B26: OBJ | C26: 1 | J26: S Moore | K26: 4 | N26: WR
A27: TE | B27: D Goedert | C27: 2 | D27: D Waller | E27: 21 | F27: K Pitts | G27: 20 | H27: G Kittle | I27: 24 | J27: N Fant | K27: 7 | L27: T Kelce | M27: 22 | N27: TE
A28: TE | B28: Z Ertz | C28: 5 | D28: D Njoku | E28: 2 | H28: P Friermuth | I28: 5 | J28: D Knox | K28: 6 | L28: H Henry | M28: 1 | N28: TE | P28: 5
A29: TE | H29: L Thomas | I29: 2 | N29: TE
A30: K | D30: D Carlson | E30: 1 | H30: T Bass | I30: 1 | J30: E McPherson | K30: 4 | L30: J. Tucker | M30: 5 | N30: K | P30: 2
A31: K | F31: C Herndon | G31: 1 | H31: M Gay | I31: 1 | J31: G Zuerlein | K31: 1 | N31: K
A32: D | B32: MIA | C32: 1 | F32: TB | G32: 2 | H32: IND | I32: 1 | J32: LAR | K32: 2 | L32: SF | M32: 1 | N32: D
A33: D | F33: PIT | G33: 2 | H33: NE | I33: 1 | N33: D
A34: WC | B34: C Wentz | C34: 1 | D34: WAS | E34: 2 | F34: M Gallup | G34: 1 | H34: C Ridley | I34: 15 | J34: D Mims | K34: 1 | L34: P Campbell | M34: 1 | N34: WC
A35: WC | B35: M Gaskin | C35: 5 | D35: Sony Michel | E35: 1 | F35: C. Hubbard | G35: 1 | J35: T Atwell | K35: 1 | L35: J Smith | M35: 1 | N35: WC
A36: WC | B36: L Shenault | C36: 2 | D36: Boston Scott | E36: 1 | F36: P. Lindsay | G36: 1 | J36: J Cook | K36: 1 | L36: P Freiermur | M36: 1 | N36: WC
A37: WC | B37: J Myers | C37: 1 | D37: Tyson Williams | E37: 1 | F37: T. Coleman | G37: 2 | J37: A Trautman | K37: 1 | L37: T Johnson | M37: 1 | N37: WC
A38: WC | B38: A Hooper | C38: 1 | D38: T Jones | E38: 1 | F38: D Harris | G38: 1 | J38: K Toney | K38: 1 | L38: D Williams | M38: 1 | N38: WC
A39: WC | B39: Z Moss | C39: 1 | D39: Russel Gage | E39: 1 | F39: P Mahomes | G39: 16 | L39: K Gainwell | M39: 1 | N39: WC
A40: WC | D40: MVS | E40: 1 | F40: R Mostert | G40: 5 | L40: J Fields | M40: 1 | N40: WC
A41: WC | D41: D Parham | E41: 1 | F41: J Tucker | G41: 2 | L41: R Succup | M41: 1 | N41: WC
...

Sheet Aaron D
A1: Aaron D
A2: Player | B2: Position | C2: Current Salary | D2: Year Drafted | E2: Contract Status | F2: Contract Year? | G2: Extending Contract? | H2: 2022-23 Salary | I2: 2023-24 Salary | J2: 2024-25 Salary | K2: 2025-26 Salary | L2: Notes
A3: T. Tagovailoa | B3: QB | C3: =H3 -> 13 | D3: 2021 | E3: =IFS('Aaron D'!G3="1 year ext.", "1 of 1 years (ext.)", 'Aaron D'!G3="2 year ext.", "1 of 2 years (ext.)", 'Aaron D'!G3="3 year ext.", "1 of 3 years (ext.)", 'Aaron D'!G3="Releasing","2 of 2 years") -> 1 of 1 years (ext.) | F3: Yes | G3: 1 year ext. | H3: 13 | I3: =IFS('Aaron D'!G3="1 year ext.", 'Aaron D'!C3+5, 'Aaron D'!G3="2 year ext.", 'Aaron D'!C3+5, 'Aaron D'!G3="3 year ext.", 'Aaron D'!C3+5, 'Aaron D'!G3="Releasing","0") -> 18 | J3: =IFS('Aaron D'!G3="1 year ext.", "0", 'Aaron D'!G3="2 year ext.", 'Aaron D'!C3+10, 'Aaron D'!G3="3 year ext.", 'Aaron D'!C3+10, 'Aaron D'!H3="Releasing","0") -> 0 | K3: =IFS('Aaron D'!G3="1 year ext.", "0", 'Aaron D'!G3="2 year ext.", "0", 'Aaron D'!G3="3 year ext.", 'Aaron D'!C3+15, 'Aaron D'!G3="Releasing","0") -> 0
A4: P. Mahomes | B4: QB | C4: =H4 -> 15 | D4: 2022 | E4: 2 of 2 Years | F4: No | H4: 15 | I4: 15
C5: =H5
A6: J. Taylor | B6: RB | C6: =H6 -> 42 | D6: 2021 | E6: =IFS('Aaron D'!G6="1 year ext.", "1 of 1 years (ext.)", 'Aaron D'!G6="2 year ext.", "1 of 2 years (ext.)", 'Aaron D'!G6="3 year ext.", "1 of 3 years (ext.)", 'Aaron D'!G6="Releasing","2 of 2 years") -> 1 of 1 years (ext.) | F6: Yes | G6: 1 year ext. | H6: 42 | I6: =IFS('Aaron D'!G6="1 year ext.", 'Aaron D'!C6+5, 'Aaron D'!G6="2 year ext.", 'Aaron D'!C6+5, 'Aaron D'!G6="3 year ext.", 'Aaron D'!C6+5, 'Aaron D'!G6="Releasing","0") -> 47 | J6: =IFS('Aaron D'!G6="1 year ext.", "0", 'Aaron D'!G6="2 year ext.", 'Aaron D'!C6+10, 'Aaron D'!G6="3 year ext.", 'Aaron D'!C6+10, 'Aaron D'!H6="Releasing","0") -> 0 | K6: =IFS('Aaron D'!G6="1 year ext.", "0", 'Aaron D'!G6="2 year ext.", "0", 'Aaron D'!G6="3 year ext.", 'Aaron D'!C6+15, 'Aaron D'!G6="Releasing","0") -> 0
A7: D. Swift | B7: RB | C7: =H7 -> 12 | D7: 2021 | E7: =IFS('Aaron D'!G7="1 year ext.", "1 of 1 years (ext.)", 'Aaron D'!G7="2 year ext.", "1 of 2 years (ext.)", 'Aaron D'!G7="3 year ext.", "1 of 3 years (ext.)", 'Aaron D'!G7="Releasing","2 of 2 years") -> 2 of 2 years | F7: Yes | G7: Releasing | H7: 12 | I7: =IFS('Aaron D'!G7="1 year ext.", 'Aaron D'!C7+5, 'Aaron D'!G7="2 year ext.", 'Aaron D'!C7+5, 'Aaron D'!G7="3 year ext.", 'Aaron D'!C7+5, 'Aaron D'!G7="Releasing","0") -> 0 | J7: =IFS('Aaron D'!G7="1 year ext.", "0", 'Aaron D'!G7="2 year ext.", 'Aaron D'!C7+10, 'Aaron D'!G7="3 year ext.", 'Aaron D'!C7+10, 'Aaron D'!G7="Releasing","0") -> 0 | K7: =IFS('Aaron D'!G7="1 year ext.", "0", 'Aaron D'!G7="2 year ext.", "0", 'Aaron D'!G7="3 year ext.", 'Aaron D'!C7+15, 'Aaron D'!G7="Releasing","0") -> 0
A8: C. Akers | B8: RB | C8: =H8 -> 3 | D8: 2021 | E8: =IFS('Aaron D'!G8="1 year ext.", "1 of 1 years (ext.)", 'Aaron D'!G8="2 year ext.", "1 of 2 years (ext.)", 'Aaron D'!G8="3 year ext.", "1 of 3 years (ext.)", 'Aaron D'!G8="Releasing","2 of 2 years") -> 1 of 2 years (ext.) | F8: Yes | G8: 2 year ext. | H8: 3 | I8: =IFS('Aaron D'!G8="1 year ext.", 'Aaron D'!C8+5, 'Aaron D'!G8="2 year ext.", 'Aaron D'!C8+5, 'Aaron D'!G8="3 year ext.", 'Aaron D'!C8+5, 'Aaron D'!G8="Releasing","0") -> 8 | J8: =IFS('Aaron D'!G8="1 year ext.", "0", 'Aaron D'!G8="2 year ext.", 'Aaron D'!C8+10, 'Aaron D'!G8="3 year ext.", 'Aaron D'!C8+10, 'Aaron D'!H8="Releasing","0") -> 13 | K8: =IFS('Aaron D'!G8="1 year ext.", "0", 'Aaron D'!G8="2 year ext.", "0", 'Aaron D'!G8="3 year ext.", 'Aaron D'!C8+15, 'Aaron D'!G8="Releasing","0") -> 0
A9: C. Edmunds | B9: RB | C9: =H9 -> 7 | D9: 2021 | E9: =IFS('Aaron D'!G9="1 year ext.", "1 of 1 years (ext.)", 'Aaron D'!G9="2 year ext.", "1 of 2 years (ext.)", 'Aaron D'!G9="3 year ext.", "1 of 3 years (ext.)", 'Aaron D'!G9="Releasing","2 of 2 years") -> 2 of 2 years | F9: Yes | G9: Releasing | H9: 7 | I9: =IFS('Aaron D'!G9="1 year ext.", 'Aaron D'!C9+5, 'Aaron D'!G9="2 year ext.", 'Aaron D'!C9+5, 'Aaron D'!G9="3 year ext.", 'Aaron D'!C9+5, 'Aaron D'!G9="Releasing","0") -> 0 | J9: =IFS('Aaron D'!G9="1 year ext.", "0", 'Aaron D'!G9="2 year ext.", 'Aaron D'!C9+10, 'Aaron D'!G9="3 year ext.", 'Aaron D'!C9+10, 'Aaron D'!G9="Releasing","0") -> 0 | K9: =IFS('Aaron D'!G9="1 year ext.", "0", 'Aaron D'!G9="2 year ext.", "0", 'Aaron D'!G9="3 year ext.", 'Aaron D'!C9+15, 'Aaron D'!G9="Releasing","0") -> 0
A10: T. Etienne | B10: RB | C10: =H10 -> 1 | D10: 2021 | E10: =IFS('Aaron D'!G10="1 year ext.", "1 of 1 years (ext.)", 'Aaron D'!G10="2 year ext.", "1 of 2 years (ext.)", 'Aaron D'!G10="3 year ext.", "1 of 3 years (ext.)", 'Aaron D'!G10="Releasing","2 of 2 years") -> 1 of 3 years (ext.) | F10: Yes | G10: 3 year ext. | H10: 1 | I10: =IFS('Aaron D'!G10="1 year ext.", 'Aaron D'!C10+5, 'Aaron D'!G10="2 year ext.", 'Aaron D'!C10+5, 'Aaron D'!G10="3 year ext.", 'Aaron D'!C10+5, 'Aaron D'!G10="Releasing","0") -> 6 | J10: =IFS('Aaron D'!G10="1 year ext.", "0", 'Aaron D'!G10="2 year ext.", 'Aaron D'!C10+10, 'Aaron D'!G10="3 year ext.", 'Aaron D'!C10+10, 'Aaron D'!G10="Releasing","0") -> 11 | K10: =IFS('Aaron D'!G10="1 year ext.", "0", 'Aaron D'!G10="2 year ext.", "0", 'Aaron D'!G10="3 year ext.", 'Aaron D'!C10+15, 'Aaron D'!G10="Releasing","0") -> 16
A11: JK Dobbins | B11: RB | C11: =H11 -> 3 | D11: 2021 | E11: =IFS('Aaron D'!G11="1 year ext.", "1 of 1 years (ext.)", 'Aaron D'!G11="2 year ext.", "1 of 2 years (ext.)", 'Aaron D'!G11="3 year ext.", "1 of 3 years (ext.)", 'Aaron D'!G11="Releasing","2 of 2 years") -> 1 of 2 years (ext.) | F11: Yes | G11: 2 year ext. | H11: 3 | I11: =IFS('Aaron D'!G11="1 year ext.", 'Aaron D'!C11+5, 'Aaron D'!G11="2 year ext.", 'Aaron D'!C11+5, 'Aaron D'!G11="3 year ext.", 'Aaron D'!C11+5, 'Aaron D'!G11="Releasing","0") -> 8 | J11: =IFS('Aaron D'!G11="1 year ext.", "0", 'Aaron D'!G11="2 year ext.", 'Aaron D'!C11+10, 'Aaron D'!G11="3 year ext.", 'Aaron D'!C11+10, 'Aaron D'!H11="Releasing","0") -> 13 | K11: =IFS('Aaron D'!G11="1 year ext.", "0", 'Aaron D'!G11="2 year ext.", "0", 'Aaron D'!G11="3 year ext.", 'Aaron D'!C11+15, 'Aaron D'!G11="Releasing","0") -> 0
A12: Kenneth Gainwell | B12: RB | C12: =H12 -> 2 | D12: 2022 | E12: 2 of 2 Years | F12: No | H12: 2 | I12: 2
C13: =H13
A14: AJ Brown | B14: WR | C14: =H14 -> 28 | D14: 2021 | E14: =IFS('Aaron D'!G14="1 year ext.", "1 of 1 years (ext.)", 'Aaron D'!G14="2 year ext.", "1 of 2 years (ext.)", 'Aaron D'!G14="3 year ext.", "1 of 3 years (ext.)", 'Aaron D'!G14="Releasing","2 of 2 years") -> 2 of 2 years | F14: Yes | G14: Releasing | H14: 28 | I14: =IFS('Aaron D'!G14="1 year ext.", 'Aaron D'!C14+5, 'Aaron D'!G14="2 year ext.", 'Aaron D'!C14+5, 'Aaron D'!G14="3 year ext.", 'Aaron D'!C14+5, 'Aaron D'!G14="Releasing","0") -> 0 | J14: =IFS('Aaron D'!G14="1 year ext.", "0", 'Aaron D'!G14="2 year ext.", 'Aaron D'!C14+10, 'Aaron D'!G14="3 year ext.", 'Aaron D'!C14+10, 'Aaron D'!G14="Releasing","0") -> 0 | K14: =IFS('Aaron D'!G14="1 year ext.", "0", 'Aaron D'!G14="2 year ext.", "0", 'Aaron D'!G14="3 year ext.", 'Aaron D'!C14+15, 'Aaron D'!G14="Releasing","0") -> 0
A15: M. Pittman | B15: WR | C15: =H15 -> 2 | D15: 2021 | E15: =IFS('Aaron D'!G15="1 year ext.", "1 of 1 years (ext.)", 'Aaron D'!G15="2 year ext.", "1 of 2 years (ext.)", 'Aaron D'!G15="3 year ext.", "1 of 3 years (ext.)", 'Aaron D'!G15="Releasing","2 of 2 years") -> 1 of 1 years (ext.) | F15: Yes | G15: 1 year ext. | H15: 2 | I15: =IFS('Aaron D'!G15="1 year ext.", 'Aaron D'!C15+5, 'Aaron D'!G15="2 year ext.", 'Aaron D'!C15+5, 'Aaron D'!G15="3 year ext.", 'Aaron D'!C15+5, 'Aaron D'!G15="Releasing","0") -> 7 | J15: =IFS('Aaron D'!G15="1 year ext.", "0", 'Aaron D'!G15="2 year ext.", 'Aaron D'!C15+10, 'Aaron D'!G15="3 year ext.", 'Aaron D'!C15+10, 'Aaron D'!H15="Releasing","0") -> 0 | K15: =IFS('Aaron D'!G15="1 year ext.", "0", 'Aaron D'!G15="2 year ext.", "0", 'Aaron D'!G15="3 year ext.", 'Aaron D'!C15+15, 'Aaron D'!G15="Releasing","0") -> 0
A16: DJ Moore | B16: WR | C16: =H16 -> 18 | D16: 2021 | E16: =IFS('Aaron D'!G16="1 year ext.", "1 of 1 years (ext.)", 'Aaron D'!G16="2 year ext.", "1 of 2 years (ext.)", 'Aaron D'!G16="3 year ext.", "1 of 3 years (ext.)", 'Aaron D'!G16="Releasing","2 of 2 years") -> 2 of 2 years | F16: Yes | G16: Releasing | H16: 18 | I16: =IFS('Aaron D'!G16="1 year ext.", 'Aaron D'!C16+5, 'Aaron D'!G16="2 year ext.", 'Aaron D'!C16+5, 'Aaron D'!G16="3 year ext.", 'Aaron D'!C16+5, 'Aaron D'!G16="Releasing","0") -> 0 | J16: =IFS('Aaron D'!G16="1 year ext.", "0", 'Aaron D'!G16="2 year ext.", 'Aaron D'!C16+10, 'Aaron D'!G16="3 year ext.", 'Aaron D'!C16+10, 'Aaron D'!G16="Releasing","0") -> 0 | K16: =IFS('Aaron D'!G16="1 year ext.", "0", 'Aaron D'!G16="2 year ext.", "0", 'Aaron D'!G16="3 year ext.", 'Aaron D'!C16+15, 'Aaron D'!G16="Releasing","0") -> 0
A17: D. Smith | B17: WR | C17: =H17 -> 11 | D17: 2021 | E17: =IFS('Aaron D'!G17="1 year ext.", "1 of 1 years (ext.)", 'Aaron D'!G17="2 year ext.", "1 of 2 years (ext.)", 'Aaron D'!G17="3 year ext.", "1 of 3 years (ext.)", 'Aaron D'!G17="Releasing","2 of 2 years") -> 1 of 2 years (ext.) | F17: Yes | G17: 2 year ext. | H17: 11 | I17: =IFS('Aaron D'!G17="1 year ext.", 'Aaron D'!C17+5, 'Aaron D'!G17="2 year ext.", 'Aaron D'!C17+5, 'Aaron D'!G17="3 year ext.", 'Aaron D'!C17+5, 'Aaron D'!G17="Releasing","0") -> 16 | J17: =IFS('Aaron D'!G17="1 year ext.", "0", 'Aaron D'!G17="2 year ext.", 'Aaron D'!C17+10, 'Aaron D'!G17="3 year ext.", 'Aaron D'!C17+10, 'Aaron D'!H17="Releasing","0") -> 21 | K17: =IFS('Aaron D'!G17="1 year ext.", "0", 'Aaron D'!G17="2 year ext.", "0", 'Aaron D'!G17="3 year ext.", 'Aaron D'!C17+15, 'Aaron D'!G17="Releasing","0") -> 0
A18: Juju | B18: WR | C18: =H18 -> 6 | D18: 2021 | E18: =IFS('Aaron D'!G18="1 year ext.", "1 of 1 years (ext.)", 'Aaron D'!G18="2 year ext.", "1 of 2 years (ext.)", 'Aaron D'!G18="3 year ext.", "1 of 3 years (ext.)", 'Aaron D'!G18="Releasing","2 of 2 years") -> 2 of 2 years | F18: Yes | G18: Releasing | H18: 6 | I18: =IFS('Aaron D'!G18="1 year ext.", 'Aaron D'!C18+5, 'Aaron D'!G18="2 year ext.", 'Aaron D'!C18+5, 'Aaron D'!G18="3 year ext.", 'Aaron D'!C18+5, 'Aaron D'!G18="Releasing","0") -> 0 | J18: =IFS('Aaron D'!G18="1 year ext.", "0", 'Aaron D'!G18="2 year ext.", 'Aaron D'!C18+10, 'Aaron D'!G18="3 year ext.", 'Aaron D'!C18+10, 'Aaron D'!G18="Releasing","0") -> 0 | K18: =IFS('Aaron D'!G18="1 year ext.", "0", 'Aaron D'!G18="2 year ext.", "0", 'Aaron D'!G18="3 year ext.", 'Aaron D'!C18+15, 'Aaron D'!G18="Releasing","0") -> 0
A19: E. Moore | B19: WR | C19: =H19 -> 3 | D19: 2021 | E19: =IFS('Aaron D'!G19="1 year ext.", "1 of 1 years (ext.)", 'Aaron D'!G19="2 year ext.", "1 of 2 years (ext.)", 'Aaron D'!G19="3 year ext.", "1 of 3 years (ext.)", 'Aaron D'!G19="Releasing","2 of 2 years") -> 1 of 3 years (ext.) | F19: Yes | G19: 3 year ext. | H19: 3 | I19: =IFS('Aaron D'!G19="1 year ext.", 'Aaron D'!C19+5, 'Aaron D'!G19="2 year ext.", 'Aaron D'!C19+5, 'Aaron D'!G19="3 year ext.", 'Aaron D'!C19+5, 'Aaron D'!G19="Releasing","0") -> 8 | J19: =IFS('Aaron D'!G19="1 year ext.", "0", 'Aaron D'!G19="2 year ext.", 'Aaron D'!C19+10, 'Aaron D'!G19="3 year ext.", 'Aaron D'!C19+10, 'Aaron D'!H19="Releasing","0") -> 13 | K19: =IFS('Aaron D'!G19="1 year ext.", "0", 'Aaron D'!G19="2 year ext.", "0", 'Aaron D'!G19="3 year ext.", 'Aaron D'!C19+15, 'Aaron D'!G19="Releasing","0") -> 18
A20: J Waddle | B20: WR | C20: =H20 -> 8 | D20: 2021 | E20: =IFS('Aaron D'!G20="1 year ext.", "1 of 1 years (ext.)", 'Aaron D'!G20="2 year ext.", "1 of 2 years (ext.)", 'Aaron D'!G20="3 year ext.", "1 of 3 years (ext.)", 'Aaron D'!G20="Releasing","2 of 2 years") -> 1 of 3 years (ext.) | F20: Yes | G20: 3 year ext. | H20: 8 | I20: =IFS('Aaron D'!G20="1 year ext.", 'Aaron D'!C20+5, 'Aaron D'!G20="2 year ext.", 'Aaron D'!C20+5, 'Aaron D'!G20="3 year ext.", 'Aaron D'!C20+5, 'Aaron D'!G20="Releasing","0") -> 13 | J20: =IFS('Aaron D'!G20="1 year ext.", "0", 'Aaron D'!G20="2 year ext.", 'Aaron D'!C20+10, 'Aaron D'!G20="3 year ext.", 'Aaron D'!C20+10, 'Aaron D'!H20="Releasing","0") -> 18 | K20: =IFS('Aaron D'!G20="1 year ext.", "0", 'Aaron D'!G20="2 year ext.", "0", 'Aaron D'!G20="3 year ext.", 'Aaron D'!C20+15, 'Aaron D'!G20="Releasing","0") -> 23
A21: OBJ | B21: WR | C21: =H21 -> 1 | D21: 2022 | E21: 2 of 2 Years | F21: No | H21: 1 | I21: 1
A22: Calvin Ridley | B22: WR | C22: =H22 -> 6 | D22: 2022 | E22: 2 of 2 Years | F22: No | H22: 6 | I22: 6
A23: Jameson Williams | B23: WR | C23: =H23 -> 9 | D23: 2022 | E23: 2 of 2 Years | F23: No | H23: 9 | I23: 9
C24: =H24
A25: D. Goddert | B25: TE | C25: =H25 -> 2 | D25: 2021 | E25: =IFS('Aaron D'!G25="1 year ext.", "1 of 1 years (ext.)", 'Aaron D'!G25="2 year ext.", "1 of 2 years (ext.)", 'Aaron D'!G25="3 year ext.", "1 of 3 years (ext.)", 'Aaron D'!G25="Releasing","2 of 2 years") -> 1 of 2 years (ext.) | F25: Yes | G25: 2 year ext. | H25: 2 | I25: =IFS('Aaron D'!G25="1 year ext.", 'Aaron D'!C25+5, 'Aaron D'!G25="2 year ext.", 'Aaron D'!C25+5, 'Aaron D'!G25="3 year ext.", 'Aaron D'!C25+5, 'Aaron D'!G25="Releasing","0") -> 7 | J25: =IFS('Aaron D'!G25="1 year ext.", "0", 'Aaron D'!G25="2 year ext.", 'Aaron D'!C25+10, 'Aaron D'!G25="3 year ext.", 'Aaron D'!C25+10, 'Aaron D'!H25="Releasing","0") -> 12 | K25: =IFS('Aaron D'!G25="1 year ext.", "0", 'Aaron D'!G25="2 year ext.", "0", 'Aaron D'!G25="3 year ext.", 'Aaron D'!C25+15, 'Aaron D'!G25="Releasing","0") -> 0
A26: Z. Ertz | B26: TE | C26: =H26 -> 5 | D26: 2022 | E26: 2 of 2 Years | F26: No | H26: 5 | I26: 5
C27: =H27
B28: K | C28: =H28
C29: =H29
A30: Miami Dolphins | B30: D | C30: =H30 -> 1 | D30: 2021 | E30: =IFS('Aaron D'!G30="1 year ext.", "1 of 1 years (ext.)", 'Aaron D'!G30="2 year ext.", "1 of 2 ext.", 'Aaron D'!G30="3 year ext.", "1 of 3 ext.", 'Aaron D'!G30="Releasing","2 of 2 years") -> 2 of 2 years | G30: Releasing | H30: 1 | I30: =IFS('Aaron D'!G30="1 year ext.", 'Aaron D'!C30+5, 'Aaron D'!G30="2 year ext.", 'Aaron D'!C30+5, 'Aaron D'!G30="3 year ext.", 'Aaron D'!C30+5, 'Aaron D'!G30="Releasing","0") -> 0 | J30: =IFS('Aaron D'!G30="1 year ext.", "0", 'Aaron D'!G30="2 year ext.", 'Aaron D'!C30+10, 'Aaron D'!G30="3 year ext.", 'Aaron D'!C30+10, 'Aaron D'!G30="Releasing","0") -> 0 | K30: =IFS('Aaron D'!G30="1 year ext.", "0", 'Aaron D'!G30="2 year ext.", "0", 'Aaron D'!G30="3 year ext.", 'Aaron D'!C30+15, 'Aaron D'!G30="Releasing","0") -> 0
C31: =H31
A32: Cut Players
A33: C. Wentz | D33: 2021 | E33: 2 of 2 years | H33: 1
A34: M. Gaskin | D34: 2021 | E34: 2 of 2 years | H34: 5
A35: L. Shenault | D35: 2021 | E35: 2 of 2 years | H35: 2
A36: J. Meyers | D36: 2021 | E36: 2 of 2 years | H36: 1
A37: A. Hooper | D37: 2021 | E37: 2 of 2 years | H37: 1
A38: Z. Moss | D38: 2021 | E38: 2 of 2 years | H38: 1
A42: TOTAL SALARY | C42: =SUM('Aaron D'!C3:'Aaron D'!C40) -> 198 | H42: =SUM('Aaron D'!H3:'Aaron D'!H40) -> 209 | I42: =SUM('Aaron D'!I3:'Aaron D'!I40) -> 176 | J42: =SUM('Aaron D'!J3:'Aaron D'!J40) -> 101 | K42: =SUM('Aaron D'!K3:'Aaron D'!K40) -> 57
A43: Salary Available | C43: =(250-'Aaron D'!C42) -> 52 | H43: =(250-'Aaron D'!H42) -> 41 | I43: =(250-'Aaron D'!I42) -> 74 | J43: =(250-'Aaron D'!J42) -> 149 | K43: =(250-'Aaron D'!K42) -> 193

Sheet Andrew M
A1: Andrew M
A2: Player | B2: Position | C2: Salary | D2: Year Drafted | E2: Status of Contract | F2: Contract Year? | G2: Extending Contract? | H2: 2022-23 Salary | I2: 2023-24 Salary | J2: 2024-25 Salary | K2: 2025-26 Salary | L2: Notes
A3: R. Tannehill | B3: QB | C3: 3 | D3: 2021 | E3: =IFS('Andrew M'!G3="1 year ext.", "1 of 1 years (ext.)", 'Andrew M'!G3="2 year ext.", "1 of 2 years (ext.)", 'Andrew M'!G3="3 year ext.", "1 of 3 years (ext.)", 'Andrew M'!G3="Releasing","2 of 2 years") -> 2 of 2 years | F3: Yes | G3: Releasing | H3: 3 | I3: =IFS('Andrew M'!G3="1 year ext.", 'Andrew M'!C3+5, 'Andrew M'!G3="2 year ext.", 'Andrew M'!C3+5, 'Andrew M'!G3="3 year ext.", 'Andrew M'!C3+5, 'Andrew M'!G3="Releasing","0") -> 0 | J3: =IFS('Andrew M'!G3="1 year ext.", "0", 'Andrew M'!G3="2 year ext.", 'Andrew M'!C3+10, 'Andrew M'!G3="3 year ext.", 'Andrew M'!C3+10, 'Andrew M'!H3="Releasing","0") -> #N/A | K3: =IFS('Andrew M'!G3="1 year ext.", "0", 'Andrew M'!G3="2 year ext.", "0", 'Andrew M'!G3="3 year ext.", 'Andrew M'!C3+15, 'Andrew M'!G3="Releasing","0") -> 0
A4: T. Lance | B4: QB | C4: 3 | D4: 2021 | E4: =IFS('Andrew M'!G4="1 year ext.", "1 of 1 years (ext.)", 'Andrew M'!G4="2 year ext.", "1 of 2 years (ext.)", 'Andrew M'!G4="3 year ext.", "1 of 3 years (ext.)", 'Andrew M'!G4="Releasing","2 of 2 years") -> 2 of 2 years | F4: Yes | G4: Releasing | H4: 3 | I4: =IFS('Andrew M'!G4="1 year ext.", 'Andrew M'!C4+5, 'Andrew M'!G4="2 year ext.", 'Andrew M'!C4+5, 'Andrew M'!G4="3 year ext.", 'Andrew M'!C4+5, 'Andrew M'!G4="Releasing","0") -> 0 | J4: =IFS('Andrew M'!G4="1 year ext.", "0", 'Andrew M'!G4="2 year ext.", 'Andrew M'!C4+10, 'Andrew M'!G4="3 year ext.", 'Andrew M'!C4+10, 'Andrew M'!H4="Releasing","0") -> #N/A | K4: =IFS('Andrew M'!G4="1 year ext.", "0", 'Andrew M'!G4="2 year ext.", "0", 'Andrew M'!G4="3 year ext.", 'Andrew M'!C4+15, 'Andrew M'!G4="Releasing","0") -> 0
A6: N. Harris | B6: RB | C6: 50 | D6: 2021 | E6: =IFS('Andrew M'!G6="1 year ext.", "1 of 1 years (ext.)", 'Andrew M'!G6="2 year ext.", "1 of 2 years (ext.)", 'Andrew M'!G6="3 year ext.", "1 of 3 years (ext.)", 'Andrew M'!G6="Releasing","2 of 2 years") -> 2 of 2 years | F6: Yes | G6: Releasing | H6: 50 | I6: =IFS('Andrew M'!G6="1 year ext.", 'Andrew M'!C6+5, 'Andrew M'!G6="2 year ext.", 'Andrew M'!C6+5, 'Andrew M'!G6="3 year ext.", 'Andrew M'!C6+5, 'Andrew M'!G6="Releasing","0") -> 0 | J6: =IFS('Andrew M'!G6="1 year ext.", "0", 'Andrew M'!G6="2 year ext.", 'Andrew M'!C6+10, 'Andrew M'!G6="3 year ext.", 'Andrew M'!C6+10, 'Andrew M'!H6="Releasing","0") -> #N/A | K6: =IFS('Andrew M'!G6="1 year ext.", "0", 'Andrew M'!G6="2 year ext.", "0", 'Andrew M'!G6="3 year ext.", 'Andrew M'!C6+15, 'Andrew M'!G6="Releasing","0") -> 0
A7: A. Gibson | B7: RB | C7: 36 | D7: 2021 | E7: =IFS('Andrew M'!G7="1 year ext.", "1 of 1 years (ext.)", 'Andrew M'!G7="2 year ext.", "1 of 2 years (ext.)", 'Andrew M'!G7="3 year ext.", "1 of 3 years (ext.)", 'Andrew M'!G7="Releasing","2 of 2 years") -> 2 of 2 years | F7: Yes | G7: Releasing | H7: 36 | I7: =IFS('Andrew M'!G7="1 year ext.", 'Andrew M'!C7+5, 'Andrew M'!G7="2 year ext.", 'Andrew M'!C7+5, 'Andrew M'!G7="3 year ext.", 'Andrew M'!C7+5, 'Andrew M'!G7="Releasing","0") -> 0 | J7: =IFS('Andrew M'!G7="1 year ext.", "0", 'Andrew M'!G7="2 year ext.", 'Andrew M'!C7+10, 'Andrew M'!G7="3 year ext.", 'Andrew M'!C7+10, 'Andrew M'!H7="Releasing","0") -> #N/A | K7: =IFS('Andrew M'!G7="1 year ext.", "0", 'Andrew M'!G7="2 year ext.", "0", 'Andrew M'!G7="3 year ext.", 'Andrew M'!C7+15, 'Andrew M'!G7="Releasing","0") -> 0
A8: T. Pollard | B8: RB | C8: 1 | D8: 2021 | E8: =IFS('Andrew M'!G8="1 year ext.", "1 of 1 years (ext.)", 'Andrew M'!G8="2 year ext.", "1 of 2 years (ext.)", 'Andrew M'!G8="3 year ext.", "1 of 3 years (ext.)", 'Andrew M'!G8="Releasing","2 of 2 years") -> 1 of 3 years (ext.) | F8: Yes | G8: 3 year ext. | H8: 1 | I8: =IFS('Andrew M'!G8="1 year ext.", 'Andrew M'!C8+5, 'Andrew M'!G8="2 year ext.", 'Andrew M'!C8+5, 'Andrew M'!G8="3 year ext.", 'Andrew M'!C8+5, 'Andrew M'!G8="Releasing","0") -> 6 | J8: =IFS('Andrew M'!G8="1 year ext.", "0", 'Andrew M'!G8="2 year ext.", 'Andrew M'!C8+10, 'Andrew M'!G8="3 year ext.", 'Andrew M'!C8+10, 'Andrew M'!H8="Releasing","0") -> 11 | K8: =IFS('Andrew M'!G8="1 year ext.", "0", 'Andrew M'!G8="2 year ext.", "0", 'Andrew M'!G8="3 year ext.", 'Andrew M'!C8+15, 'Andrew M'!G8="Releasing","0") -> 16
A9: Kenneth Walker | B9: RB | C9: 14 | D9: 2022 | E9: 1 of 2 years | F9: No | H9: 14
A10: M. Ingram | B10: RB | C10: 4 | D10: 2021 | E10: 1 of 2 years | F10: No | H10: 4
A12: S. Diggs | B12: WR | C12: 45 | D12: 2021 | E12: =IFS('Andrew M'!G12="1 year ext.", "1 of 1 years (ext.)", 'Andrew M'!G12="2 year ext.", "1 of 2 years (ext.)", 'Andrew M'!G12="3 year ext.", "1 of 3 years (ext.)", 'Andrew M'!G12="Releasing","2 of 2 years") -> 1 of 2 years (ext.) | F12: Yes | G12: 2 year ext. | H12: 45 | I12: =IFS('Andrew M'!G12="1 year ext.", 'Andrew M'!C12+5, 'Andrew M'!G12="2 year ext.", 'Andrew M'!C12+5, 'Andrew M'!G12="3 year ext.", 'Andrew M'!C12+5, 'Andrew M'!G12="Releasing","0") -> 50 | J12: =IFS('Andrew M'!G12="1 year ext.", "0", 'Andrew M'!G12="2 year ext.", 'Andrew M'!C12+10, 'Andrew M'!G12="3 year ext.", 'Andrew M'!C12+10, 'Andrew M'!H12="Releasing","0") -> 55 | K12: =IFS('Andrew M'!G12="1 year ext.", "0", 'Andrew M'!G12="2 year ext.", "0", 'Andrew M'!G12="3 year ext.", 'Andrew M'!C12+15, 'Andrew M'!G12="Releasing","0") -> 0
A13: Aiyuk | B13: WR | C13: 15 | D13: 2021 | E13: =IFS('Andrew M'!G13="1 year ext.", "1 of 1 years (ext.)", 'Andrew M'!G13="2 year ext.", "1 of 2 years (ext.)", 'Andrew M'!G13="3 year ext.", "1 of 3 years (ext.)", 'Andrew M'!G13="Releasing","2 of 2 years") -> 2 of 2 years | F13: Yes | G13: Releasing | H13: 15 | I13: =IFS('Andrew M'!G13="1 year ext.", 'Andrew M'!C13+5, 'Andrew M'!G13="2 year ext.", 'Andrew M'!C13+5, 'Andrew M'!G13="3 year ext.", 'Andrew M'!C13+5, 'Andrew M'!G13="Releasing","0") -> 0 | J13: =IFS('Andrew M'!G13="1 year ext.", "0", 'Andrew M'!G13="2 year ext.", 'Andrew M'!C13+10, 'Andrew M'!G13="3 year ext.", 'Andrew M'!C13+10, 'Andrew M'!H13="Releasing","0") -> #N/A | K13: =IFS('Andrew M'!G13="1 year ext.", "0", 'Andrew M'!G13="2 year ext.", "0", 'Andrew M'!G13="3 year ext.", 'Andrew M'!C13+15, 'Andrew M'!G13="Releasing","0") -> 0
A14: M. Thomas | B14: WR | C14: 7 | D14: 2021 | E14: =IFS('Andrew M'!G14="1 year ext.", "1 of 1 years (ext.)", 'Andrew M'!G14="2 year ext.", "1 of 2 years (ext.)", 'Andrew M'!G14="3 year ext.", "1 of 3 years (ext.)", 'Andrew M'!G14="Releasing","2 of 2 years") -> 2 of 2 years | F14: Yes | G14: Releasing | H14: 7 | I14: =IFS('Andrew M'!G14="1 year ext.", 'Andrew M'!C14+5, 'Andrew M'!G14="2 year ext.", 'Andrew M'!C14+5, 'Andrew M'!G14="3 year ext.", 'Andrew M'!C14+5, 'Andrew M'!G14="Releasing","0") -> 0 | J14: =IFS('Andrew M'!G14="1 year ext.", "0", 'Andrew M'!G14="2 year ext.", 'Andrew M'!C14+10, 'Andrew M'!G14="3 year ext.", 'Andrew M'!C14+10, 'Andrew M'!H14="Releasing","0") -> #N/A | K14: =IFS('Andrew M'!G14="1 year ext.", "0", 'Andrew M'!G14="2 year ext.", "0", 'Andrew M'!G14="3 year ext.", 'Andrew M'!C14+15, 'Andrew M'!G14="Releasing","0") -> 0
A15: D. Mooney | B15: WR | C15: 3 | D15: 2021 | E15: =IFS('Andrew M'!G15="1 year ext.", "1 of 1 years (ext.)", 'Andrew M'!G15="2 year ext.", "1 of 2 years (ext.)", 'Andrew M'!G15="3 year ext.", "1 of 3 years (ext.)", 'Andrew M'!G15="Releasing","2 of 2 years") -> 2 of 2 years | F15: Yes | G15: Releasing | H15: 3 | I15: =IFS('Andrew M'!G15="1 year ext.", 'Andrew M'!C15+5, 'Andrew M'!G15="2 year ext.", 'Andrew M'!C15+5, 'Andrew M'!G15="3 year ext.", 'Andrew M'!C15+5, 'Andrew M'!G15="Releasing","0") -> 0 | J15: =IFS('Andrew M'!G15="1 year ext.", "0", 'Andrew M'!G15="2 year ext.", 'Andrew M'!C15+10, 'Andrew M'!G15="3 year ext.", 'Andrew M'!C15+10, 'Andrew M'!H15="Releasing","0") -> #N/A | K15: =IFS('Andrew M'!G15="1 year ext.", "0", 'Andrew M'!G15="2 year ext.", "0", 'Andrew M'!G15="3 year ext.", 'Andrew M'!C15+15, 'Andrew M'!G15="Releasing","0") -> 0
A16: C. Olave | B16: WR | C16: 18 | D16: 2022 | E16: 1 of 2 years | F16: No | H16: 18
A17: B. Edwards | B17: WR | C17: 1 | D17: 2021 | E17: =IFS('Andrew M'!G17="1 year ext.", "1 of 1 years (ext.)", 'Andrew M'!G17="2 year ext.", "1 of 2 years (ext.)", 'Andrew M'!G17="3 year ext.", "1 of 3 years (ext.)", 'Andrew M'!G17="Releasing","2 of 2 years") -> 2 of 2 years | F17: Yes | G17: Releasing | H17: 1 | I17: =IFS('Andrew M'!G17="1 year ext.", 'Andrew M'!C17+5, 'Andrew M'!G17="2 year ext.", 'Andrew M'!C17+5, 'Andrew M'!G17="3 year ext.", 'Andrew M'!C17+5, 'Andrew M'!G17="Releasing","0") -> 0 | J17: =IFS('Andrew M'!G17="1 year ext.", "0", 'Andrew M'!G17="2 year ext.", 'Andrew M'!C17+10, 'Andrew M'!G17="3 year ext.", 'Andrew M'!C17+10, 'Andrew M'!H17="Releasing","0") -> #N/A | K17: =IFS('Andrew M'!G17="1 year ext.", "0", 'Andrew M'!G17="2 year ext.", "0", 'Andrew M'!G17="3 year ext.", 'Andrew M'!C17+15, 'Andrew M'!G17="Releasing","0") -> 0
A18: J. Meyers | B18: WR | C18: 1 | D18: 2021 | E18: =IFS('Andrew M'!G18="1 year ext.", "1 of 1 years (ext.)", 'Andrew M'!G18="2 year ext.", "1 of 2 years (ext.)", 'Andrew M'!G18="3 year ext.", "1 of 3 years (ext.)", 'Andrew M'!G18="Releasing","2 of 2 years") -> 2 of 2 years | F18: Yes | G18: Releasing | H18: 1 | I18: =IFS('Andrew M'!G18="1 year ext.", 'Andrew M'!C18+5, 'Andrew M'!G18="2 year ext.", 'Andrew M'!C18+5, 'Andrew M'!G18="3 year ext.", 'Andrew M'!C18+5, 'Andrew M'!G18="Releasing","0") -> 0 | J18: =IFS('Andrew M'!G18="1 year ext.", "0", 'Andrew M'!G18="2 year ext.", 'Andrew M'!C18+10, 'Andrew M'!G18="3 year ext.", 'Andrew M'!C18+10, 'Andrew M'!H18="Releasing","0") -> #N/A | K18: =IFS('Andrew M'!G18="1 year ext.", "0", 'Andrew M'!G18="2 year ext.", "0", 'Andrew M'!G18="3 year ext.", 'Andrew M'!C18+15, 'Andrew M'!G18="Releasing","0") -> 0
A19: Garrett Wilson | B19: WR | C19: 6 | D19: 2022 | E19: 1 of 2 years | F19: No | H19: 6
A21: D. Waller | B21: TE | C21: 21 | D21: 2021 | E21: =IFS('Andrew M'!G21="1 year ext.", "1 of 1 years (ext.)", 'Andrew M'!G21="2 year ext.", "1 of 2 years (ext.)", 'Andrew M'!G21="3 year ext.", "1 of 3 years (ext.)", 'Andrew M'!G21="Releasing","2 of 2 years") -> 1 of 1 years (ext.) | F21: Yes | G21: 1 year ext. | H21: 21 | I21: =IFS('Andrew M'!G21="1 year ext.", 'Andrew M'!C21+5, 'Andrew M'!G21="2 year ext.", 'Andrew M'!C21+5, 'Andrew M'!G21="3 year ext.", 'Andrew M'!C21+5, 'Andrew M'!G21="Releasing","0") -> 26 | J21: =IFS('Andrew M'!G21="1 year ext.", "0", 'Andrew M'!G21="2 year ext.", 'Andrew M'!C21+10, 'Andrew M'!G21="3 year ext.", 'Andrew M'!C21+10, 'Andrew M'!H21="Releasing","0") -> 0 | K21: =IFS('Andrew M'!G21="1 year ext.", "0", 'Andrew M'!G21="2 year ext.", "0", 'Andrew M'!G21="3 year ext.", 'Andrew M'!C21+15, 'Andrew M'!G21="Releasing","0") -> 0
A22: David Njoku | B22: TE | C22: 2 | D22: 2022 | E22: 1 of 2 years | F22: No | H22: 2
A24: D. Carlson | B24: K | C24: 1 | D24: 2021 | E24: =IFS('Andrew M'!G24="1 year ext.", "1 of 1 years (ext.)", 'Andrew M'!G24="2 year ext.", "1 of 2 years (ext.)", 'Andrew M'!G24="3 year ext.", "1 of 3 years (ext.)", 'Andrew M'!G24="Releasing","2 of 2 years") -> 2 of 2 years | F24: Yes | G24: Releasing | H24: 1 | I24: =IFS('Andrew M'!G24="1 year ext.", 'Andrew M'!C24+5, 'Andrew M'!G24="2 year ext.", 'Andrew M'!C24+5, 'Andrew M'!G24="3 year ext.", 'Andrew M'!C24+5, 'Andrew M'!G24="Releasing","0") -> 0 | J24: =IFS('Andrew M'!G24="1 year ext.", "0", 'Andrew M'!G24="2 year ext.", 'Andrew M'!C24+10, 'Andrew M'!G24="3 year ext.", 'Andrew M'!C24+10, 'Andrew M'!H24="Releasing","0") -> #N/A | K24: =IFS('Andrew M'!G24="1 year ext.", "0", 'Andrew M'!G24="2 year ext.", "0", 'Andrew M'!G24="3 year ext.", 'Andrew M'!C24+15, 'Andrew M'!G24="Releasing","0") -> 0
B26: DEF
A29: Cut Players
A30: Washington DEF | D30: 2021 | E30: 2 of 2 years | H30: 2
A31: Sony Michel | D31: 2021 | E31: 2 of 2 years | H31: 1
A32: Boston Scott | D32: 2021 | E32: 2 of 2 years | H32: 1
A33: Tyson Williams | D33: 2021 | E33: 2 of 2 years | H33: 1
A34: T. Jones | D34: 2021 | E34: 2 of 2 years | H34: 1
A35: Russell Gage | D35: 2021 | E35: 2 of 2 years | H35: 1
A36: MVS | D36: 2021 | E36: 2 of 2 years | H36: 1
A37: D. Parham | D37: 2021 | E37: 2 of 2 years | H37: 1
A39: TOTAL SALARY | C39: =SUM('Andrew M'!C3:C37) -> 231 | H39: =SUM('Andrew M'!H3:H37) -> 240 | I39: =SUM('Andrew M'!I3:I37) -> 82 | J39: =SUM('Andrew M'!J3:J37) -> #N/A | K39: =SUM('Andrew M'!K3:K37) -> 16
A40: Salary Available | C40: =(250-'Andrew M'!C39) -> 19 | H40: =(250-'Andrew M'!H39) -> 10 | I40: =(250-'Andrew M'!I39) -> 168 | J40: =(250-'Andrew M'!J39) -> #N/A | K40: =(250-'Andrew M'!K39) -> 234

Sheet Caleb K
A1: Caleb K
A2: Player | B2: Position | C2: Salary | D2: Year Drafted | E2: Status of Contract | F2: Contract Year? | G2: Extending Contract? | H2: 2022-23 Salary | I2: 2023-24 Salary | J2: 2024-25 Salary | K2: 2025-26 Salary | L2: Notes
A3: K. Pickett | B3: QB | C3: 5 | D3: 2022 | E3: 2 of 2 years | F3: No | H3: 5 | I3: 5 | J3: 0
A4: L. Jackson | B4: QB | C4: 17 | D4: 2021 | E4: =IFS('Caleb K'!G4="1 year ext.", "1 of 1 years (ext.)", 'Caleb K'!G4="2 year ext.", "1 of 2 years (ext.)", 'Caleb K'!G4="3 year ext.", "1 of 3 years (ext.)", 'Caleb K'!G4="Releasing","2 of 2 years") -> 2 of 2 years | F4: Yes | G4: Releasing | H4: 17 | I4: =IFS('Caleb K'!G4="1 year ext.", 'Caleb K'!C4+5, 'Caleb K'!G4="2 year ext.", 'Caleb K'!C4+5, 'Caleb K'!G4="3 year ext.", 'Caleb K'!C4+5, 'Caleb K'!G4="Releasing","0") -> 0 | J4: =IFS('Caleb K'!G4="1 year ext.", "0", 'Caleb K'!G4="2 year ext.", 'Caleb K'!C4+10, 'Caleb K'!G4="3 year ext.", 'Caleb K'!C4+10, 'Caleb K'!G4="Releasing","0") -> 0 | K4: =IFS('Caleb K'!G4="1 year ext.", "0", 'Caleb K'!G4="2 year ext.", "0", 'Caleb K'!G4="3 year ext.", 'Caleb K'!C4+15, 'Caleb K'!G4="Releasing","0") -> 0
A5: T. Brady | B5: QB | C5: 3 | D5: 2021 | E5: =IFS('Caleb K'!G5="1 year ext.", "1 of 1 years (ext.)", 'Caleb K'!G5="2 year ext.", "1 of 2 years (ext.)", 'Caleb K'!G5="3 year ext.", "1 of 3 years (ext.)", 'Caleb K'!G5="Releasing","2 of 2 years") -> 2 of 2 years | F5: Yes | G5: Releasing | H5: 3 | I5: =IFS('Caleb K'!G5="1 year ext.", 'Caleb K'!C5+5, 'Caleb K'!G5="2 year ext.", 'Caleb K'!C5+5, 'Caleb K'!G5="3 year ext.", 'Caleb K'!C5+5, 'Caleb K'!G5="Releasing","0") -> 0 | J5: =IFS('Caleb K'!G5="1 year ext.", "0", 'Caleb K'!G5="2 year ext.", 'Caleb K'!C5+10, 'Caleb K'!G5="3 year ext.", 'Caleb K'!C5+10, 'Caleb K'!G5="Releasing","0") -> 0 | K5: =IFS('Caleb K'!G5="1 year ext.", "0", 'Caleb K'!G5="2 year ext.", "0", 'Caleb K'!G5="3 year ext.", 'Caleb K'!C5+15, 'Caleb K'!G5="Releasing","0") -> 0
A6: D. Watson | B6: QB | C6: 2 | D6: 2021 | E6: =IFS('Caleb K'!G6="1 year ext.", "1 of 1 years (ext.)", 'Caleb K'!G6="2 year ext.", "1 of 2 years (ext.)", 'Caleb K'!G6="3 year ext.", "1 of 3 years (ext.)", 'Caleb K'!G6="Releasing","2 of 2 years") -> 1 of 3 years (ext.) | F6: Yes | G6: 3 year ext. | H6: 2 | I6: =IFS('Caleb K'!G6="1 year ext.", 'Caleb K'!C6+5, 'Caleb K'!G6="2 year ext.", 'Caleb K'!C6+5, 'Caleb K'!G6="3 year ext.", 'Caleb K'!C6+5, 'Caleb K'!G6="Releasing","0") -> 7 | J6: =IFS('Caleb K'!G6="1 year ext.", "0", 'Caleb K'!G6="2 year ext.", 'Caleb K'!C6+10, 'Caleb K'!G6="3 year ext.", 'Caleb K'!C6+10, 'Caleb K'!H6="Releasing","0") -> 12 | K6: =IFS('Caleb K'!G6="1 year ext.", "0", 'Caleb K'!G6="2 year ext.", "0", 'Caleb K'!G6="3 year ext.", 'Caleb K'!C6+15, 'Caleb K'!G6="Releasing","0") -> 17
A8: Breece Hall | B8: RB | C8: 28 | D8: 2022 | E8: 2 of 2 years | F8: No | H8: 28 | I8: 28
A9: D. Singletary | B9: RB | C9: 3 | D9: 2021 | E9: =IFS('Caleb K'!G9="1 year ext.", "1 of 1 years (ext.)", 'Caleb K'!G9="2 year ext.", "1 of 2 years (ext.)", 'Caleb K'!G9="3 year ext.", "1 of 3 years (ext.)", 'Caleb K'!G9="Releasing","2 of 2 years") -> 2 of 2 years | F9: Yes | G9: Releasing | H9: 3 | I9: =IFS('Caleb K'!G9="1 year ext.", 'Caleb K'!C9+5, 'Caleb K'!G9="2 year ext.", 'Caleb K'!C9+5, 'Caleb K'!G9="3 year ext.", 'Caleb K'!C9+5, 'Caleb K'!G9="Releasing","0") -> 0 | J9: =IFS('Caleb K'!G9="1 year ext.", "0", 'Caleb K'!G9="2 year ext.", 'Caleb K'!C9+10, 'Caleb K'!G9="3 year ext.", 'Caleb K'!C9+10, 'Caleb K'!G9="Releasing","0") -> 0 | K9: =IFS('Caleb K'!G9="1 year ext.", "0", 'Caleb K'!G9="2 year ext.", "0", 'Caleb K'!G9="3 year ext.", 'Caleb K'!C9+15, 'Caleb K'!G9="Releasing","0") -> 0
A10: K. Drake | B10: RB | C10: 2 | D10: 2021 | E10: =IFS('Caleb K'!G10="1 year ext.", "1 of 1 years (ext.)", 'Caleb K'!G10="2 year ext.", "1 of 2 years (ext.)", 'Caleb K'!G10="3 year ext.", "1 of 3 years (ext.)", 'Caleb K'!G10="Releasing","2 of 2 years") -> 2 of 2 years | F10: Yes | G10: Releasing | H10: 2 | I10: =IFS('Caleb K'!G10="1 year ext.", 'Caleb K'!C10+5, 'Caleb K'!G10="2 year ext.", 'Caleb K'!C10+5, 'Caleb K'!G10="3 year ext.", 'Caleb K'!C10+5, 'Caleb K'!G10="Releasing","0") -> 0 | J10: =IFS('Caleb K'!G10="1 year ext.", "0", 'Caleb K'!G10="2 year ext.", 'Caleb K'!C10+10, 'Caleb K'!G10="3 year ext.", 'Caleb K'!C10+10, 'Caleb K'!G10="Releasing","0") -> 0 | K10: =IFS('Caleb K'!G10="1 year ext.", "0", 'Caleb K'!G10="2 year ext.", "0", 'Caleb K'!G10="3 year ext.", 'Caleb K'!C10+15, 'Caleb K'!G10="Releasing","0") -> 0
A11: D. Pierce | B11: RB | C11: 29 | D11: 2022 | E11: 2 of 2 years | F11: No | H11: 29 | I11: 29
A12: R. Stevensen | B12: RB | C12: 1 | D12: 2021 | E12: =IFS('Caleb K'!G12="1 year ext.", "1 of 1 years (ext.)", 'Caleb K'!G12="2 year ext.", "1 of 2 years (ext.)", 'Caleb K'!G12="3 year ext.", "1 of 3 years (ext.)", 'Caleb K'!G12="Releasing","2 of 2 years") -> 1 of 3 years (ext.) | F12: Yes | G12: 3 year ext. | H12: 1 | I12: =IFS('Caleb K'!G12="1 year ext.", 'Caleb K'!C12+5, 'Caleb K'!G12="2 year ext.", 'Caleb K'!C12+5, 'Caleb K'!G12="3 year ext.", 'Caleb K'!C12+5, 'Caleb K'!G12="Releasing","0") -> 6 | J12: =IFS('Caleb K'!G12="1 year ext.", "0", 'Caleb K'!G12="2 year ext.", 'Caleb K'!C12+10, 'Caleb K'!G12="3 year ext.", 'Caleb K'!C12+10, 'Caleb K'!H12="Releasing","0") -> 11 | K12: =IFS('Caleb K'!G12="1 year ext.", "0", 'Caleb K'!G12="2 year ext.", "0", 'Caleb K'!G12="3 year ext.", 'Caleb K'!C12+15, 'Caleb K'!G12="Releasing","0") -> 16
A14: T. Hill | B14: WR | C14: 37 | D14: 2021 | E14: =IFS('Caleb K'!G14="1 year ext.", "1 of 1 years (ext.)", 'Caleb K'!G14="2 year ext.", "1 of 2 years (ext.)", 'Caleb K'!G14="3 year ext.", "1 of 3 years (ext.)", 'Caleb K'!G14="Releasing","2 of 2 years") -> 1 of 1 years (ext.) | F14: Yes | G14: 1 year ext. | H14: 37 | I14: =IFS('Caleb K'!G14="1 year ext.", 'Caleb K'!C14+5, 'Caleb K'!G14="2 year ext.", 'Caleb K'!C14+5, 'Caleb K'!G14="3 year ext.", 'Caleb K'!C14+5, 'Caleb K'!G14="Releasing","0") -> 42 | J14: =IFS('Caleb K'!G14="1 year ext.", "0", 'Caleb K'!G14="2 year ext.", 'Caleb K'!C14+10, 'Caleb K'!G14="3 year ext.", 'Caleb K'!C14+10, 'Caleb K'!H14="Releasing","0") -> 0 | K14: =IFS('Caleb K'!G14="1 year ext.", "0", 'Caleb K'!G14="2 year ext.", "0", 'Caleb K'!G14="3 year ext.", 'Caleb K'!C14+15, 'Caleb K'!G14="Releasing","0") -> 0
A15: C. Godwin | B15: WR | C15: 15 | D15: 2021 | E15: =IFS('Caleb K'!G15="1 year ext.", "1 of 1 years (ext.)", 'Caleb K'!G15="2 year ext.", "1 of 2 years (ext.)", 'Caleb K'!G15="3 year ext.", "1 of 3 years (ext.)", 'Caleb K'!G15="Releasing","2 of 2 years") -> 2 of 2 years | F15: Yes | G15: Releasing | H15: 15 | I15: =IFS('Caleb K'!G15="1 year ext.", 'Caleb K'!C15+5, 'Caleb K'!G15="2 year ext.", 'Caleb K'!C15+5, 'Caleb K'!G15="3 year ext.", 'Caleb K'!C15+5, 'Caleb K'!G15="Releasing","0") -> 0 | J15: =IFS('Caleb K'!G15="1 year ext.", "0", 'Caleb K'!G15="2 year ext.", 'Caleb K'!C15+10, 'Caleb K'!G15="3 year ext.", 'Caleb K'!C15+10, 'Caleb K'!G15="Releasing","0") -> 0 | K15: =IFS('Caleb K'!G15="1 year ext.", "0", 'Caleb K'!G15="2 year ext.", "0", 'Caleb K'!G15="3 year ext.", 'Caleb K'!C15+15, 'Caleb K'!G15="Releasing","0") -> 0
A16: R. Woods | B16: WR | C16: 15 | D16: 2021 | E16: =IFS('Caleb K'!G16="1 year ext.", "1 of 1 years (ext.)", 'Caleb K'!G16="2 year ext.", "1 of 2 years (ext.)", 'Caleb K'!G16="3 year ext.", "1 of 3 years (ext.)", 'Caleb K'!G16="Releasing","2 of 2 years") -> 2 of 2 years | F16: Yes | G16: Releasing | H16: 15 | I16: =IFS('Caleb K'!G16="1 year ext.", 'Caleb K'!C16+5, 'Caleb K'!G16="2 year ext.", 'Caleb K'!C16+5, 'Caleb K'!G16="3 year ext.", 'Caleb K'!C16+5, 'Caleb K'!G16="Releasing","0") -> 0 | J16: =IFS('Caleb K'!G16="1 year ext.", "0", 'Caleb K'!G16="2 year ext.", 'Caleb K'!C16+10, 'Caleb K'!G16="3 year ext.", 'Caleb K'!C16+10, 'Caleb K'!G16="Releasing","0") -> 0 | K16: =IFS('Caleb K'!G16="1 year ext.", "0", 'Caleb K'!G16="2 year ext.", "0", 'Caleb K'!G16="3 year ext.", 'Caleb K'!C16+15, 'Caleb K'!G16="Releasing","0") -> 0
A17: J. Landry | B17: WR | C17: 3 | D17: 2021 | E17: =IFS('Caleb K'!G17="1 year ext.", "1 of 1 years (ext.)", 'Caleb K'!G17="2 year ext.", "1 of 2 years (ext.)", 'Caleb K'!G17="3 year ext.", "1 of 3 years (ext.)", 'Caleb K'!G17="Releasing","2 of 2 years") -> 2 of 2 years | F17: Yes | G17: Releasing | H17: 3 | I17: =IFS('Caleb K'!G17="1 year ext.", 'Caleb K'!C17+5, 'Caleb K'!G17="2 year ext.", 'Caleb K'!C17+5, 'Caleb K'!G17="3 year ext.", 'Caleb K'!C17+5, 'Caleb K'!G17="Releasing","0") -> 0 | J17: =IFS('Caleb K'!G17="1 year ext.", "0", 'Caleb K'!G17="2 year ext.", 'Caleb K'!C17+10, 'Caleb K'!G17="3 year ext.", 'Caleb K'!C17+10, 'Caleb K'!G17="Releasing","0") -> 0 | K17: =IFS('Caleb K'!G17="1 year ext.", "0", 'Caleb K'!G17="2 year ext.", "0", 'Caleb K'!G17="3 year ext.", 'Caleb K'!C17+15, 'Caleb K'!G17="Releasing","0") -> 0
A18: K. Toney | B18: WR | C18: 20 | D18: 2022 | E18: 2 of 2 years | F18: No | H18: 20 | I18: 20
A19: J. Dotson | B19: WR | C19: 7 | D19: 2022 | E19: 2 of 2 years | F19: No | H19: 7 | I19: 7
A20: W. Fuller | B20: WR | C20: 2 | D20: 2021 | E20: =IFS('Caleb K'!G20="1 year ext.", "1 of 1 years (ext.)", 'Caleb K'!G20="2 year ext.", "1 of 2 years (ext.)", 'Caleb K'!G20="3 year ext.", "1 of 3 years (ext.)", 'Caleb K'!G20="Releasing","2 of 2 years") -> 2 of 2 years | F20: Yes | G20: Releasing | H20: 2 | I20: =IFS('Caleb K'!G20="1 year ext.", 'Caleb K'!C20+5, 'Caleb K'!G20="2 year ext.", 'Caleb K'!C20+5, 'Caleb K'!G20="3 year ext.", 'Caleb K'!C20+5, 'Caleb K'!G20="Releasing","0") -> 0 | J20: =IFS('Caleb K'!G20="1 year ext.", "0", 'Caleb K'!G20="2 year ext.", 'Caleb K'!C20+10, 'Caleb K'!G20="3 year ext.", 'Caleb K'!C20+10, 'Caleb K'!G20="Releasing","0") -> 0 | K20: =IFS('Caleb K'!G20="1 year ext.", "0", 'Caleb K'!G20="2 year ext.", "0", 'Caleb K'!G20="3 year ext.", 'Caleb K'!C20+15, 'Caleb K'!G20="Releasing","0") -> 0
A22: K. Pitts | B22: TE | C22: 20 | D22: 2021 | E22: =IFS('Caleb K'!G22="1 year ext.", "1 of 1 years (ext.)", 'Caleb K'!G22="2 year ext.", "1 of 2 years (ext.)", 'Caleb K'!G22="3 year ext.", "1 of 3 years (ext.)", 'Caleb K'!G22="Releasing","2 of 2 years") -> 2 of 2 years | F22: Yes | G22: Releasing | H22: 20 | I22: =IFS('Caleb K'!G22="1 year ext.", 'Caleb K'!C22+5, 'Caleb K'!G22="2 year ext.", 'Caleb K'!C22+5, 'Caleb K'!G22="3 year ext.", 'Caleb K'!C22+5, 'Caleb K'!G22="Releasing","0") -> 0 | J22: =IFS('Caleb K'!G22="1 year ext.", "0", 'Caleb K'!G22="2 year ext.", 'Caleb K'!C22+10, 'Caleb K'!G22="3 year ext.", 'Caleb K'!C22+10, 'Caleb K'!G22="Releasing","0") -> 0 | K22: =IFS('Caleb K'!G22="1 year ext.", "0", 'Caleb K'!G22="2 year ext.", "0", 'Caleb K'!G22="3 year ext.", 'Caleb K'!C22+15, 'Caleb K'!G22="Releasing","0") -> 0
A24: Tampa Bay | B24: D | C24: 2 | D24: 2021 | E24: =IFS('Caleb K'!G24="1 year ext.", "1 of 1 years (ext.)", 'Caleb K'!G24="2 year ext.", "1 of 2 years (ext.)", 'Caleb K'!G24="3 year ext.", "1 of 3 years (ext.)", 'Caleb K'!G24="Releasing","2 of 2 years") -> 2 of 2 years | F24: Yes | G24: Releasing | H24: 2 | I24: =IFS('Caleb K'!G24="1 year ext.", 'Caleb K'!C24+5, 'Caleb K'!G24="2 year ext.", 'Caleb K'!C24+5, 'Caleb K'!G24="3 year ext.", 'Caleb K'!C24+5, 'Caleb K'!G24="Releasing","0") -> 0 | J24: =IFS('Caleb K'!G24="1 year ext.", "0", 'Caleb K'!G24="2 year ext.", 'Caleb K'!C24+10, 'Caleb K'!G24="3 year ext.", 'Caleb K'!C24+10, 'Caleb K'!G24="Releasing","0") -> 0 | K24: =IFS('Caleb K'!G24="1 year ext.", "0", 'Caleb K'!G24="2 year ext.", "0", 'Caleb K'!G24="3 year ext.", 'Caleb K'!C24+15, 'Caleb K'!G24="Releasing","0") -> 0
A25: Pit | B25: D | C25: 2 | D25: 2021 | E25: =IFS('Caleb K'!G25="1 year ext.", "1 of 1 years (ext.)", 'Caleb K'!G25="2 year ext.", "1 of 2 years (ext.)", 'Caleb K'!G25="3 year ext.", "1 of 3 years (ext.)", 'Caleb K'!G25="Releasing","2 of 2 years") -> 2 of 2 years | F25: Yes | G25: Releasing | H25: 2 | I25: =IFS('Caleb K'!G25="1 year ext.", 'Caleb K'!C25+5, 'Caleb K'!G25="2 year ext.", 'Caleb K'!C25+5, 'Caleb K'!G25="3 year ext.", 'Caleb K'!C25+5, 'Caleb K'!G25="Releasing","0") -> 0 | J25: =IFS('Caleb K'!G25="1 year ext.", "0", 'Caleb K'!G25="2 year ext.", 'Caleb K'!C25+10, 'Caleb K'!G25="3 year ext.", 'Caleb K'!C25+10, 'Caleb K'!G25="Releasing","0") -> 0 | K25: =IFS('Caleb K'!G25="1 year ext.", "0", 'Caleb K'!G25="2 year ext.", "0", 'Caleb K'!G25="3 year ext.", 'Caleb K'!C25+15, 'Caleb K'!G25="Releasing","0") -> 0
A30: Cut Players
A31: M. Gallup | D31: 2021 | E31: 2 of 2 years | H31: 1
A32: Chubba Hubbard | D32: 2021 | E32: 2 of 2 years | H32: 1
A33: P. Lindsay | D33: 2021 | E33: 2 of 2 years | H33: 1
A34: T. Coleman | D34: 2021 | E34: 2 of 2 years | H34: 2
A35: D. Harris | D35: 2021 | E35: 2 of 2 years | H35: 1
A36: Pat Mahomes | D36: 2021 | E36: 2 of 2 years | H36: 16
A37: R. Mostert | D37: 2021 | E37: 2 of 2 years | H37: 5
A38: C. Herndon | D38: 2021 | E38: 2 of 2 years | H38: 1
A39: J Tucker | D39: 2021 | E39: 2 of 2 years | H39: 2
A41: TOTAL SALARY | C41: =SUM('Caleb K'!C3:C39) -> 213 | H41: =SUM('Caleb K'!H3:H39) -> 243 | I41: =SUM('Caleb K'!I3:I39) -> 144 | J41: =SUM('Caleb K'!J3:J39) -> 23 | K41: =SUM('Caleb K'!K3:K39) -> 33
A42: Salary Available | C42: =(250-'Caleb K'!C41) -> 37 | H42: =(250-'Caleb K'!H41) -> 7 | I42: =(250-'Caleb K'!I41) -> 106 | J42: =(250-'Caleb K'!J41) -> 227 | K42: =(250-'Caleb K'!K41) -> 217

Sheet Chris G
A1: Chris G
A2: Player | B2: Position | C2: Current Salary | D2: Year Drafted | E2: Status of Contract | F2: Contract Year? | G2: Extending Contract? | H2: 2022-23 Salary | I2: 2023-24 Salary | J2: 2024-25 Salary | K2: 2025-26 Salary | L2: Notes
A3: D. Prescott | B3: QB | C3: 8 | D3: 2021 | E3: =IFS('Chris G'!G3="1 year ext.", "1 of 1 years (ext.)", 'Chris G'!G3="2 year ext.", "1 of 2 ext.", 'Chris G'!G3="3 year ext.", "1 of 3 ext.", 'Chris G'!G3="Releasing","2 of 2 years") -> 1 of 1 years (ext.) | F3: Yes | G3: 1 year ext. | H3: 8 | I3: =IFS('Chris G'!G3="1 year ext.", 'Chris G'!C3+5, 'Chris G'!G3="2 year ext.", 'Chris G'!C3+5, 'Chris G'!G3="3 year ext.", 'Chris G'!C3+5, 'Chris G'!G3="Releasing","0") -> 13 | J3: =IFS('Chris G'!G3="1 year ext.", "0", 'Chris G'!G3="2 year ext.", 'Chris G'!C3+10, 'Chris G'!G3="3 year ext.", 'Chris G'!C3+10, 'Chris G'!G3="Releasing","0") -> 0 | K3: =IFS('Chris G'!G3="1 year ext.", "0", 'Chris G'!G3="2 year ext.", "0", 'Chris G'!G3="3 year ext.", 'Chris G'!C3+15, 'Chris G'!G3="Releasing","0") -> 0
A4: M. Stafford | B4: QB | C4: 3 | D4: 2021 | E4: =IFS('Chris G'!G4="1 year ext.", "1 of 1 years (ext.)", 'Chris G'!G4="2 year ext.", "1 of 2 ext.", 'Chris G'!G4="3 year ext.", "1 of 3 ext.", 'Chris G'!G4="Releasing","2 of 2 years") -> 1 of 1 years (ext.) | F4: Yes | G4: 1 year ext. | H4: 3 | I4: =IFS('Chris G'!G4="1 year ext.", 'Chris G'!C4+5, 'Chris G'!G4="2 year ext.", 'Chris G'!C4+5, 'Chris G'!G4="3 year ext.", 'Chris G'!C4+5, 'Chris G'!G4="Releasing","0") -> 8 | J4: =IFS('Chris G'!G4="1 year ext.", "0", 'Chris G'!G4="2 year ext.", 'Chris G'!C4+10, 'Chris G'!G4="3 year ext.", 'Chris G'!C4+10, 'Chris G'!G4="Releasing","0") -> 0 | K4: =IFS('Chris G'!G4="1 year ext.", "0", 'Chris G'!G4="2 year ext.", "0", 'Chris G'!G4="3 year ext.", 'Chris G'!C4+15, 'Chris G'!G4="Releasing","0") -> 0
A6: J. Jacobs | B6: RB | C6: 28 | D6: 2021 | E6: =IFS('Chris G'!G6="1 year ext.", "1 of 1 years (ext.)", 'Chris G'!G6="2 year ext.", "1 of 2 ext.", 'Chris G'!G6="3 year ext.", "1 of 3 ext.", 'Chris G'!G6="Releasing","2 of 2 years") -> 1 of 1 years (ext.) | F6: Yes | G6: 1 year ext. | H6: 28 | I6: =IFS('Chris G'!G6="1 year ext.", 'Chris G'!C6+5, 'Chris G'!G6="2 year ext.", 'Chris G'!C6+5, 'Chris G'!G6="3 year ext.", 'Chris G'!C6+5, 'Chris G'!G6="Releasing","0") -> 33 | J6: =IFS('Chris G'!G6="1 year ext.", "0", 'Chris G'!G6="2 year ext.", 'Chris G'!C6+10, 'Chris G'!G6="3 year ext.", 'Chris G'!C6+10, 'Chris G'!G6="Releasing","0") -> 0 | K6: =IFS('Chris G'!G6="1 year ext.", "0", 'Chris G'!G6="2 year ext.", "0", 'Chris G'!G6="3 year ext.", 'Chris G'!C6+15, 'Chris G'!G6="Releasing","0") -> 0
A7: A. Ekeler | B7: RB | C7: 29 | D7: 2021 | E7: =IFS('Chris G'!G7="1 year ext.", "1 of 1 years (ext.)", 'Chris G'!G7="2 year ext.", "1 of 2 ext.", 'Chris G'!G7="3 year ext.", "1 of 3 ext.", 'Chris G'!G7="Releasing","2 of 2 years") -> 1 of 2 ext. | F7: Yes | G7: 2 year ext. | H7: 29 | I7: =IFS('Chris G'!G7="1 year ext.", 'Chris G'!C7+5, 'Chris G'!G7="2 year ext.", 'Chris G'!C7+5, 'Chris G'!G7="3 year ext.", 'Chris G'!C7+5, 'Chris G'!G7="Releasing","0") -> 34 | J7: =IFS('Chris G'!G7="1 year ext.", "0", 'Chris G'!G7="2 year ext.", 'Chris G'!C7+10, 'Chris G'!G7="3 year ext.", 'Chris G'!C7+10, 'Chris G'!G7="Releasing","0") -> 39 | K7: =IFS('Chris G'!G7="1 year ext.", "0", 'Chris G'!G7="2 year ext.", "0", 'Chris G'!G7="3 year ext.", 'Chris G'!C7+15, 'Chris G'!G7="Releasing","0") -> 0
A8: I. Spiller | B8: RB | C8: 6 | D8: 2022 | E8: 2 of 2 years | F8: No | H8: 6
A9: J. Connor | B9: RB | C9: 2 | D9: 2021 | E9: =IFS('Chris G'!G9="1 year ext.", "1 of 1 years (ext.)", 'Chris G'!G9="2 year ext.", "1 of 2 ext.", 'Chris G'!G9="3 year ext.", "1 of 3 ext.", 'Chris G'!G9="Releasing","2 of 2 years") -> 1 of 2 ext. | F9: Yes | G9: 2 year ext. | H9: 2 | I9: =IFS('Chris G'!G9="1 year ext.", 'Chris G'!C9+5, 'Chris G'!G9="2 year ext.", 'Chris G'!C9+5, 'Chris G'!G9="3 year ext.", 'Chris G'!C9+5, 'Chris G'!G9="Releasing","0") -> 7 | J9: =IFS('Chris G'!G9="1 year ext.", "0", 'Chris G'!G9="2 year ext.", 'Chris G'!C9+10, 'Chris G'!G9="3 year ext.", 'Chris G'!C9+10, 'Chris G'!G9="Releasing","0") -> 12 | K9: =IFS('Chris G'!G9="1 year ext.", "0", 'Chris G'!G9="2 year ext.", "0", 'Chris G'!G9="3 year ext.", 'Chris G'!C9+15, 'Chris G'!G9="Releasing","0") -> 0
A10: N. Hines | B10: RB | C10: 1 | D10: 2021 | E10: =IFS('Chris G'!G10="1 year ext.", "1 of 1 years (ext.)", 'Chris G'!G10="2 year ext.", "1 of 2 ext.", 'Chris G'!G10="3 year ext.", "1 of 3 ext.", 'Chris G'!G10="Releasing","2 of 2 years") -> 2 of 2 years | F10: Yes | G10: Releasing | H10: 1 | I10: =IFS('Chris G'!G10="1 year ext.", 'Chris G'!C10+5, 'Chris G'!G10="2 year ext.", 'Chris G'!C10+5, 'Chris G'!G10="3 year ext.", 'Chris G'!C10+5, 'Chris G'!G10="Releasing","0") -> 0 | J10: =IFS('Chris G'!G10="1 year ext.", "0", 'Chris G'!G10="2 year ext.", 'Chris G'!C10+10, 'Chris G'!G10="3 year ext.", 'Chris G'!C10+10, 'Chris G'!G10="Releasing","0") -> 0 | K10: =IFS('Chris G'!G10="1 year ext.", "0", 'Chris G'!G10="2 year ext.", "0", 'Chris G'!G10="3 year ext.", 'Chris G'!C10+15, 'Chris G'!G10="Releasing","0") -> 0
A11: J. White | B11: RB | C11: 1 | D11: 2021 | E11: =IFS('Chris G'!G11="1 year ext.", "1 of 1 years (ext.)", 'Chris G'!G11="2 year ext.", "1 of 2 ext.", 'Chris G'!G11="3 year ext.", "1 of 3 ext.", 'Chris G'!G11="Releasing","2 of 2 years") -> 2 of 2 years | F11: Yes | G11: Releasing | H11: 1 | I11: =IFS('Chris G'!G11="1 year ext.", 'Chris G'!C11+5, 'Chris G'!G11="2 year ext.", 'Chris G'!C11+5, 'Chris G'!G11="3 year ext.", 'Chris G'!C11+5, 'Chris G'!G11="Releasing","0") -> 0 | J11: =IFS('Chris G'!G11="1 year ext.", "0", 'Chris G'!G11="2 year ext.", 'Chris G'!C11+10, 'Chris G'!G11="3 year ext.", 'Chris G'!C11+10, 'Chris G'!G11="Releasing","0") -> 0 | K11: =IFS('Chris G'!G11="1 year ext.", "0", 'Chris G'!G11="2 year ext.", "0", 'Chris G'!G11="3 year ext.", 'Chris G'!C11+15, 'Chris G'!G11="Releasing","0") -> 0
A12: Rachaad White | B12: RB | C12: 4 | D12: 2022 | E12: 2 of 2 years | F12: No | H12: 4
A14: C. Lamb | B14: WR | C14: 20 | D14: 2021 | E14: =IFS('Chris G'!G14="1 year ext.", "1 of 1 years (ext.)", 'Chris G'!G14="2 year ext.", "1 of 2 ext.", 'Chris G'!G14="3 year ext.", "1 of 3 ext.", 'Chris G'!G14="Releasing","2 of 2 years") -> 1 of 3 ext. | F14: Yes | G14: 3 year ext. | H14: 20 | I14: =IFS('Chris G'!G14="1 year ext.", 'Chris G'!C14+5, 'Chris G'!G14="2 year ext.", 'Chris G'!C14+5, 'Chris G'!G14="3 year ext.", 'Chris G'!C14+5, 'Chris G'!G14="Releasing","0") -> 25 | J14: =IFS('Chris G'!G14="1 year ext.", "0", 'Chris G'!G14="2 year ext.", 'Chris G'!C14+10, 'Chris G'!G14="3 year ext.", 'Chris G'!C14+10, 'Chris G'!G14="Releasing","0") -> 30 | K14: =IFS('Chris G'!G14="1 year ext.", "0", 'Chris G'!G14="2 year ext.", "0", 'Chris G'!G14="3 year ext.", 'Chris G'!C14+15, 'Chris G'!G14="Releasing","0") -> 35
A15: K. Allen | B15: WR | C15: 24 | D15: 2021 | E15: =IFS('Chris G'!G15="1 year ext.", "1 of 1 years (ext.)", 'Chris G'!G15="2 year ext.", "1 of 2 ext.", 'Chris G'!G15="3 year ext.", "1 of 3 ext.", 'Chris G'!G15="Releasing","2 of 2 years") -> 1 of 1 years (ext.) | F15: Yes | G15: 1 year ext. | H15: 24 | I15: =IFS('Chris G'!G15="1 year ext.", 'Chris G'!C15+5, 'Chris G'!G15="2 year ext.", 'Chris G'!C15+5, 'Chris G'!G15="3 year ext.", 'Chris G'!C15+5, 'Chris G'!G15="Releasing","0") -> 29 | J15: =IFS('Chris G'!G15="1 year ext.", "0", 'Chris G'!G15="2 year ext.", 'Chris G'!C15+10, 'Chris G'!G15="3 year ext.", 'Chris G'!C15+10, 'Chris G'!G15="Releasing","0") -> 0 | K15: =IFS('Chris G'!G15="1 year ext.", "0", 'Chris G'!G15="2 year ext.", "0", 'Chris G'!G15="3 year ext.", 'Chris G'!C15+15, 'Chris G'!G15="Releasing","0") -> 0
A16: C. Davis | B16: WR | C16: 3 | D16: 2021 | E16: =IFS('Chris G'!G16="1 year ext.", "1 of 1 years (ext.)", 'Chris G'!G16="2 year ext.", "1 of 2 ext.", 'Chris G'!G16="3 year ext.", "1 of 3 ext.", 'Chris G'!G16="Releasing","2 of 2 years") -> 2 of 2 years | F16: Yes | G16: Releasing | H16: 3 | I16: =IFS('Chris G'!G16="1 year ext.", 'Chris G'!C16+5, 'Chris G'!G16="2 year ext.", 'Chris G'!C16+5, 'Chris G'!G16="3 year ext.", 'Chris G'!C16+5, 'Chris G'!G16="Releasing","0") -> 0 | J16: =IFS('Chris G'!G16="1 year ext.", "0", 'Chris G'!G16="2 year ext.", 'Chris G'!C16+10, 'Chris G'!G16="3 year ext.", 'Chris G'!C16+10, 'Chris G'!G16="Releasing","0") -> 0 | K16: =IFS('Chris G'!G16="1 year ext.", "0", 'Chris G'!G16="2 year ext.", "0", 'Chris G'!G16="3 year ext.", 'Chris G'!C16+15, 'Chris G'!G16="Releasing","0") -> 0
A17: S. Shepard | B17: WR | C17: 1 | D17: 2021 | E17: =IFS('Chris G'!G17="1 year ext.", "1 of 1 years (ext.)", 'Chris G'!G17="2 year ext.", "1 of 2 ext.", 'Chris G'!G17="3 year ext.", "1 of 3 ext.", 'Chris G'!G17="Releasing","2 of 2 years") -> 2 of 2 years | F17: Yes | G17: Releasing | H17: 1 | I17: =IFS('Chris G'!G17="1 year ext.", 'Chris G'!C17+5, 'Chris G'!G17="2 year ext.", 'Chris G'!C17+5, 'Chris G'!G17="3 year ext.", 'Chris G'!C17+5, 'Chris G'!G17="Releasing","0") -> 0 | J17: =IFS('Chris G'!G17="1 year ext.", "0", 'Chris G'!G17="2 year ext.", 'Chris G'!C17+10, 'Chris G'!G17="3 year ext.", 'Chris G'!C17+10, 'Chris G'!G17="Releasing","0") -> 0 | K17: =IFS('Chris G'!G17="1 year ext.", "0", 'Chris G'!G17="2 year ext.", "0", 'Chris G'!G17="3 year ext.", 'Chris G'!C17+15, 'Chris G'!G17="Releasing","0") -> 0
A18: R. Bateman | B18: WR | C18: 1 | D18: 2021 | E18: =IFS('Chris G'!G18="1 year ext.", "1 of 1 years (ext.)", 'Chris G'!G18="2 year ext.", "1 of 2 ext.", 'Chris G'!G18="3 year ext.", "1 of 3 ext.", 'Chris G'!G18="Releasing","2 of 2 years") -> 1 of 2 ext. | F18: Yes | G18: 2 year ext. | H18: 1 | I18: =IFS('Chris G'!G18="1 year ext.", 'Chris G'!C18+5, 'Chris G'!G18="2 year ext.", 'Chris G'!C18+5, 'Chris G'!G18="3 year ext.", 'Chris G'!C18+5, 'Chris G'!G18="Releasing","0") -> 6 | J18: =IFS('Chris G'!G18="1 year ext.", "0", 'Chris G'!G18="2 year ext.", 'Chris G'!C18+10, 'Chris G'!G18="3 year ext.", 'Chris G'!C18+10, 'Chris G'!G18="Releasing","0") -> 11 | K18: =IFS('Chris G'!G18="1 year ext.", "0", 'Chris G'!G18="2 year ext.", "0", 'Chris G'!G18="3 year ext.", 'Chris G'!C18+15, 'Chris G'!G18="Releasing","0") -> 0
A19: George Pickens | B19: WR | C19: 12 | D19: 2022 | E19: 2 of 2 years | F19: No | H19: 12
A20: Romeo Doubs | B20: WR | C20: 8 | D20: 2022 | E20: 2 of 2 years | F20: No | H20: 8
A22: G. Kittle | B22: TE | C22: 24 | D22: 2021 | E22: =IFS('Chris G'!G22="1 year ext.", "1 of 1 years (ext.)", 'Chris G'!G22="2 year ext.", "1 of 2 ext.", 'Chris G'!G22="3 year ext.", "1 of 3 ext.", 'Chris G'!G22="Releasing","2 of 2 years") -> 1 of 1 years (ext.) | F22: Yes | G22: 1 year ext. | H22: 24 | I22: =IFS('Chris G'!G22="1 year ext.", 'Chris G'!C22+5, 'Chris G'!G22="2 year ext.", 'Chris G'!C22+5, 'Chris G'!G22="3 year ext.", 'Chris G'!C22+5, 'Chris G'!G22="Releasing","0") -> 29 | J22: =IFS('Chris G'!G22="1 year ext.", "0", 'Chris G'!G22="2 year ext.", 'Chris G'!C22+10, 'Chris G'!G22="3 year ext.", 'Chris G'!C22+10, 'Chris G'!G22="Releasing","0") -> 0 | K22: =IFS('Chris G'!G22="1 year ext.", "0", 'Chris G'!G22="2 year ext.", "0", 'Chris G'!G22="3 year ext.", 'Chris G'!C22+15, 'Chris G'!G22="Releasing","0") -> 0
A23: L. Thomas | B23: TE | C23: 2 | D23: 2021 | E23: =IFS('Chris G'!G23="1 year ext.", "1 of 1 years (ext.)", 'Chris G'!G23="2 year ext.", "1 of 2 ext.", 'Chris G'!G23="3 year ext.", "1 of 3 ext.", 'Chris G'!G23="Releasing","2 of 2 years") -> 2 of 2 years | F23: Yes | G23: Releasing | H23: 2 | I23: =IFS('Chris G'!G23="1 year ext.", 'Chris G'!C23+5, 'Chris G'!G23="2 year ext.", 'Chris G'!C23+5, 'Chris G'!G23="3 year ext.", 'Chris G'!C23+5, 'Chris G'!G23="Releasing","0") -> 0 | J23: =IFS('Chris G'!G23="1 year ext.", "0", 'Chris G'!G23="2 year ext.", 'Chris G'!C23+10, 'Chris G'!G23="3 year ext.", 'Chris G'!C23+10, 'Chris G'!G23="Releasing","0") -> 0 | K23: =IFS('Chris G'!G23="1 year ext.", "0", 'Chris G'!G23="2 year ext.", "0", 'Chris G'!G23="3 year ext.", 'Chris G'!C23+15, 'Chris G'!G23="Releasing","0") -> 0
A24: Pat Friermuth | B24: TE | C24: 5 | D24: 2022 | E24: 2 of 2 years | F24: No | H24: 5
A26: T. Bass | B26: K | C26: 1 | D26: 2021 | E26: =IFS('Chris G'!G26="1 year ext.", "1 of 1 years (ext.)", 'Chris G'!G26="2 year ext.", "1 of 2 ext.", 'Chris G'!G26="3 year ext.", "1 of 3 ext.", 'Chris G'!G26="Releasing","2 of 2 years") -> 2 of 2 years | F26: Yes | G26: Releasing | H26: 1 | I26: =IFS('Chris G'!G26="1 year ext.", 'Chris G'!C26+5, 'Chris G'!G26="2 year ext.", 'Chris G'!C26+5, 'Chris G'!G26="3 year ext.", 'Chris G'!C26+5, 'Chris G'!G26="Releasing","0") -> 0 | J26: =IFS('Chris G'!G26="1 year ext.", "0", 'Chris G'!G26="2 year ext.", 'Chris G'!C26+10, 'Chris G'!G26="3 year ext.", 'Chris G'!C26+10, 'Chris G'!G26="Releasing","0") -> 0 | K26: =IFS('Chris G'!G26="1 year ext.", "0", 'Chris G'!G26="2 year ext.", "0", 'Chris G'!G26="3 year ext.", 'Chris G'!C26+15, 'Chris G'!G26="Releasing","0") -> 0
A27: M. Gay | B27: K | C27: 1 | D27: 2021 | E27: =IFS('Chris G'!G27="1 year ext.", "1 of 1 years (ext.)", 'Chris G'!G27="2 year ext.", "1 of 2 ext.", 'Chris G'!G27="3 year ext.", "1 of 3 ext.", 'Chris G'!G27="Releasing","2 of 2 years") -> 2 of 2 years | F27: Yes | G27: Releasing | H27: 1 | I27: =IFS('Chris G'!G27="1 year ext.", 'Chris G'!C27+5, 'Chris G'!G27="2 year ext.", 'Chris G'!C27+5, 'Chris G'!G27="3 year ext.", 'Chris G'!C27+5, 'Chris G'!G27="Releasing","0") -> 0 | J27: =IFS('Chris G'!G27="1 year ext.", "0", 'Chris G'!G27="2 year ext.", 'Chris G'!C27+10, 'Chris G'!G27="3 year ext.", 'Chris G'!C27+10, 'Chris G'!G27="Releasing","0") -> 0 | K27: =IFS('Chris G'!G27="1 year ext.", "0", 'Chris G'!G27="2 year ext.", "0", 'Chris G'!G27="3 year ext.", 'Chris G'!C27+15, 'Chris G'!G27="Releasing","0") -> 0
